<?xml version="1.0" encoding="utf-8"?>
<!-- This URDF was automatically created by SolidWorks to URDF Exporter! Originally created by
Stephen Brawner (brawner@gmail.com) 
     Commit Version: 1.6.0-4-g7f85cfe  Build Version: 1.6.7995.38578
     For more information, please see http://wiki.ros.org/sw_urdf_exporter -->

<robot name="Master_ASM" xmlns:xacro="http://www.ros.org/wiki/xacro">
  <link name="base_link">
    <origin xyz="0 0 0" rpy="0 0 0" />
  </link>
  <joint name="base_to_frame_joint" type="fixed">
    <parent link="base_link" />
    <child link="frame_link" />
    <origin xyz="0 0 0" rpy="0 0 -1.5708" />
  </joint>
  <link
    name="frame_link">
    <inertial>
      <origin
        xyz="0.0012829 -0.31468 -0.0059364"
        rpy="0 0 0" />
      <mass
        value="38.039" />
      <inertia
        ixx="0.51975"
        ixy="0.00069908"
        ixz="2.9544E-06"
        iyy="0.93889"
        iyz="-3.8081E-06"
        izz="0.5273" />
    </inertial>
    <visual>
      <origin
        xyz="0 0 0"
        rpy="0 0 0" />
      <geometry>
        <mesh
          filename="package://robot_description/models/master_ASM/meshes/frame_link.STL" />
      </geometry>
      <material
        name="">
        <color
          rgba="0.79216 0.81961 0.93333 1" />
      </material>
    </visual>
    <collision>
      <origin
        xyz="0 0 -0.2"
        rpy="0 0 0" />
      <geometry>
        <box size="0.7317 1.4254 0.6435" />
      </geometry>
    </collision>
  </link>

  <xacro:arg name="use_zed_localization" default="true" />
  <xacro:include filename="$(find zed_wrapper)/urdf/zed_macro.urdf.xacro" />

   <!-- Add the first ZED Camera -->  
  <xacro:zed_camera name="zed2i" model="zed2i" enable_gnss="false">
    <!-- This block is required even if enable_gnss="false" for some reason, but you can leave it empty -->
    <gnss_origin></gnss_origin>
  </xacro:zed_camera>

  <!-- Add the second ZED Camera -->
  <xacro:zed_camera name="zed2i_rear" model="zed2i" enable_gnss="false">
    <!-- This block is required even if enable_gnss="false" for some reason, but you can leave it empty -->
    <gnss_origin></gnss_origin>
  </xacro:zed_camera>

  <xacro:if value="$(arg use_zed_localization)">
    <!-- ZED Localization -> The reference link is 'zed2i_camera_link' and 'base_link' is a child -->
    <joint name="zed2i_joint" type="fixed">
      <parent link="zed2i_camera_link"/>
      <child link="base_link"/>
      <origin xyz="-0.5 0 0.375" rpy="0 0 0"/>
    </joint>    
  </xacro:if>
  <xacro:unless value="$(arg use_zed_localization)">
    <!-- NO ZED Localization -> 'zed2i_camera_link' is a child of 'base_link' -->
    <joint name="zed2i_joint" type="fixed">
      <parent link="base_link"/>
      <child link="zed2i_camera_link"/>
      <origin xyz="0.5 0 -0.375" rpy="0 0 0"/>
    </joint>
  </xacro:unless>
  
  <joint name="zed2i_rear_joint" type="fixed">
    <parent link="base_link"/>
    <child link="zed2i_rear_camera_link"/>
    <origin xyz="0.5 0 -0.375" rpy="0 0 ${M_PI}"/>
  </joint>

  <gazebo reference="zed2i_camera_link">
    <sensor name="camera" type="camera">
      <always_on>true</always_on>
      <update_rate>30</update_rate>
      <camera>
        <horizontal_fov>1.91986218</horizontal_fov> 
        <image>
          <format>R8G8B8</format>
          <width>1280</width>
          <height>720</height>
        </image>
        <clip>
          <near>0.3</near>
          <far>5.0</far>
        </clip>
      </camera>
      <topic>/color/image</topic>
      <info_topic>/color/camera_info</info_topic>
      <gz_frame_id>zed2i_left_camera_optical_frame</gz_frame_id>
    </sensor>
    <sensor name="depthcamera" type="depth">
      <always_on>true</always_on>
      <update_rate>30</update_rate>
      <camera>
        <horizontal_fov>1.91986218</horizontal_fov> 
        <image>
          <format>R8G8B8</format>
          <width>1280</width>
          <height>720</height>
        </image>
        <clip>
          <near>0.3</near>
          <far>20.0</far>
        </clip>
      </camera>
      <topic>/depth/image</topic>
      <info_topic>/depth/camera_info</info_topic>
      <gz_frame_id>zed2i_left_camera_optical_frame</gz_frame_id>
    </sensor>
  </gazebo>

  <!-- TODO: Test if this works in Gazebo (both ZEDs) -->
  <!-- <gazebo reference="zed2i_rear_camera_link">
    <sensor name="camera_rear" type="camera">
      <always_on>true</always_on>
      <update_rate>30</update_rate>
      <camera>
        <horizontal_fov>1.91986218</horizontal_fov> 
        <image>
          <format>R8G8B8</format>
          <width>1280</width>
          <height>720</height>
        </image>
        <clip>
          <near>0.3</near>
          <far>5.0</far>
        </clip>
      </camera>
      <topic>/color/image_rear</topic>
      <info_topic>/color/camera_info_rear</info_topic>
      <gz_frame_id>zed2i_rear_left_camera_optical_frame</gz_frame_id>
    </sensor>
    <sensor name="depthcamera_rear" type="depth">
      <always_on>true</always_on>
      <update_rate>30</update_rate>
      <camera>
        <horizontal_fov>1.91986218</horizontal_fov> 
        <image>
          <format>R8G8B8</format>
          <width>1280</width>
          <height>720</height>
        </image>
        <clip>
          <near>0.3</near>
          <far>20.0</far>
        </clip>
      </camera>
      <topic>/depth/image_rear</topic>
      <info_topic>/depth/camera_info_rear</info_topic>
      <gz_frame_id>zed2i_rear_left_camera_optical_frame</gz_frame_id>
    </sensor>
  </gazebo> -->

  <link
    name="swerve1_Link">
    <inertial>
      <origin
        xyz="0.072878 0.028694 7.0574E-06"
        rpy="0 0 0" />
      <mass
        value="2.5211" />
      <inertia
        ixx="0.008233"
        ixy="5.8978E-05"
        ixz="5.7912E-08"
        iyy="0.006818"
        iyz="1.2459E-07"
        izz="0.0069443" />
    </inertial>
    <visual>
      <origin
        xyz="0 0 0"
        rpy="0 0 0" />
      <geometry>
        <box size="0.1 0.2 0.1" />
      </geometry>
      <material
        name="">
        <color
          rgba="0.75294 0.75294 0.75294 1" />
      </material>
    </visual>
  </link>
  <joint
    name="swerve1_joint"
    type="fixed">
    <origin
      xyz="-0.34701 0.55026 -0.59563"
      rpy="1.5708 0 0" />
    <parent
      link="frame_link" />
    <child
      link="swerve1_Link" />
    <axis
      xyz="0 1 0" />
    <!-- <limit lower="6.28" upper="6.28" effort="30" velocity="1.0" /> -->
  </joint>
  <link
    name="wheel1_Link">
    <inertial>
      <origin
        xyz="2.9097E-09 -0.115 -0.00055956"
        rpy="0 0 0" />
      <mass
        value="1.1372" />
      <inertia
        ixx="0.0059462"
        ixy="1.6529E-09"
        ixz="-6.3363E-10"
        iyy="0.0059468"
        iyz="6.9163E-09"
        izz="0.0072591" />
    </inertial>
    <visual>
      <origin
        xyz="0 0.115 0"
        rpy="0 0 0" />
      <geometry>
        <mesh
          filename="package://robot_description/models/master_ASM/meshes/wheel_Link.STL" />
      </geometry>
      <material
        name="">
        <color
          rgba="0.79216 0.81961 0.93333 1" />
      </material>
    </visual>
    <collision>
      <origin
        xyz="0 0 0"
        rpy="0 0 0" />
      <geometry>
        <cylinder radius="0.115" length="0.2" />
      </geometry>
    </collision>
  </link>
  <joint
    name="wheel1_joint"
    type="continuous">
    <origin
      xyz="0 0 0"
      rpy="1.5708 0.34561 1.5708" />
    <parent
      link="swerve1_Link" />
    <child
      link="wheel1_Link" />
    <axis
      xyz="0 0 -1" />
  </joint>
  <link
    name="swerve2_Link">
    <inertial>
      <origin
        xyz="0.072878 0.028694 7.0574E-06"
        rpy="0 0 0" />
      <mass
        value="2.5211" />
      <inertia
        ixx="0.008233"
        ixy="5.8978E-05"
        ixz="5.7912E-08"
        iyy="0.006818"
        iyz="1.2459E-07"
        izz="0.0069443" />
    </inertial>
    <visual>
      <origin
        xyz="0 0 0"
        rpy="0 0 0" />
      <geometry>
        <box size="0.1 0.2 0.1" />
      </geometry>
      <material
        name="">
        <color
          rgba="0.75294 0.75294 0.75294 1" />
      </material>
    </visual>
  </link>
  <joint
    name="swerve2_joint"
    type="fixed">
    <origin
      xyz="0.34701 -0.55026 -0.59563"
      rpy="1.5708 0 3.1416" />
    <parent
      link="frame_link" />
    <child
      link="swerve2_Link" />
    <axis
      xyz="0 1 0" />
    <!-- <limit lower="6.28" upper="6.28" effort="30" velocity="1.0" /> -->
  </joint>
  <link
    name="wheel2_Link">
    <inertial>
      <origin
        xyz="2.9097E-09 -0.115 -0.00055956"
        rpy="0 0 0" />
      <mass
        value="1.1372" />
      <inertia
        ixx="0.0059462"
        ixy="1.6529E-09"
        ixz="-6.3363E-10"
        iyy="0.0059468"
        iyz="6.9163E-09"
        izz="0.0072591" />
    </inertial>
    <visual>
      <origin
        xyz="0 0.115 0"
        rpy="0 0 0" />
      <geometry>
        <mesh
          filename="package://robot_description/models/master_ASM/meshes/wheel_Link.STL" />
      </geometry>
      <material
        name="">
        <color
          rgba="0.79216 0.81961 0.93333 1" />
      </material>
    </visual>
    <collision>
      <origin
        xyz="0 0 0"
        rpy="0 0 0" />
      <geometry>
        <!-- <mesh
          filename="package://Master_ASM/meshes/wheel2_Link.STL" /> -->
        <cylinder radius="0.115" length="0.2" />
      </geometry>
    </collision>
  </link>
  <joint
    name="wheel2_joint"
    type="continuous">
    <origin
      xyz="0 0 0"
      rpy="1.5708 0.34561 1.5708" />
    <parent
      link="swerve2_Link" />
    <child
      link="wheel2_Link" />
    <axis
      xyz="0 0 1" />
  </joint>
  <link
    name="swerve3_Link">
    <inertial>
      <origin
        xyz="0.072878 0.028694 7.0574E-06"
        rpy="0 0 0" />
      <mass
        value="2.5211" />
      <inertia
        ixx="0.008233"
        ixy="5.8978E-05"
        ixz="5.7912E-08"
        iyy="0.006818"
        iyz="1.2459E-07"
        izz="0.0069443" />
    </inertial>
    <visual>
      <origin
        xyz="0 0 0"
        rpy="0 0 0" />
      <geometry>
        <box size="0.1 0.2 0.1" />
      </geometry>
      <material
        name="">
        <color
          rgba="0.75294 0.75294 0.75294 1" />
      </material>
    </visual>
  </link>
  <joint
    name="swerve3_joint"
    type="fixed">
    <origin
      xyz="0.34701 0.55014 -0.59563"
      rpy="1.5708 0 3.1416" />
    <parent
      link="frame_link" />
    <child
      link="swerve3_Link" />
    <axis
      xyz="0 1 0" />
  </joint>
  <link
    name="wheel3_Link">
    <inertial>
      <origin
        xyz="2.9097E-09 -0.115 -0.00055956"
        rpy="0 0 0" />
      <mass
        value="1.1372" />
      <inertia
        ixx="0.0059462"
        ixy="1.6529E-09"
        ixz="-6.3363E-10"
        iyy="0.0059468"
        iyz="6.9163E-09"
        izz="0.0072591" />
    </inertial>
    <visual>
      <origin
        xyz="0 0.115 0"
        rpy="0 0 0" />
      <geometry>
        <mesh
          filename="package://robot_description/models/master_ASM/meshes/wheel_Link.STL" />
      </geometry>
      <material
        name="">
        <color
          rgba="0.79216 0.81961 0.93333 1" />
      </material>
    </visual>
    <collision>
      <origin
        xyz="0 0 0"
        rpy="0 0 0" />
      <geometry>
        <cylinder radius="0.115" length="0.2" />
      </geometry>
    </collision>
  </link>
  <joint
    name="wheel3_joint"
    type="continuous">
    <origin
      xyz="0 0 0"
      rpy="1.5708 0.34561 1.5708" />
    <parent
      link="swerve3_Link" />
    <child
      link="wheel3_Link" />
    <axis
      xyz="0 0 1" />
  </joint>
  <link
    name="swerve4_Link">
    <inertial>
      <origin
        xyz="0.072878 0.028694 7.0574E-06"
        rpy="0 0 0" />
      <mass
        value="2.5211" />
      <inertia
        ixx="0.008233"
        ixy="5.8978E-05"
        ixz="5.7912E-08"
        iyy="0.006818"
        iyz="1.2459E-07"
        izz="0.0069443" />
    </inertial>
    <visual>
      <origin
        xyz="0 0 0"
        rpy="0 0 0" />
      <geometry>
        <box size="0.1 0.2 0.1" />
      </geometry>
      <material
        name="">
        <color
          rgba="0.75294 0.75294 0.75294 1" />
      </material>
    </visual>
  </link>
  <joint
    name="swerve4_joint"
    type="fixed">
    <origin
      xyz="-0.34701 -0.55014 -0.59563"
      rpy="1.5708 0 0" />
    <parent
      link="frame_link" />
    <child
      link="swerve4_Link" />
    <axis
      xyz="0 1 0" />
  </joint>
  <link
    name="wheel4_Link">
    <inertial>
      <origin
        xyz="2.9097E-09 -0.115 -0.00055956"
        rpy="0 0 0" />
      <mass
        value="1.1372" />
      <inertia
        ixx="0.0059462"
        ixy="1.6529E-09"
        ixz="-6.3363E-10"
        iyy="0.0059468"
        iyz="6.9163E-09"
        izz="0.0072591" />
    </inertial>
    <visual>
      <origin
        xyz="0 0.115 0"
        rpy="0 0 0" />
      <geometry>
        <mesh
          filename="package://robot_description/models/master_ASM/meshes/wheel_Link.STL" />
      </geometry>
      <material
        name="">
        <color
          rgba="0.79216 0.81961 0.93333 1" />
      </material>
    </visual>
    <collision>
      <origin
        xyz="0 0 0"
        rpy="0 0 0" />
      <geometry>
        <cylinder radius="0.115" length="0.2" />
      </geometry>
    </collision>
  </link>
  <joint
    name="wheel4_joint"
    type="continuous">
    <origin
      xyz="0 0 0"
      rpy="1.5708 0.34561 1.5708" />
    <parent
      link="swerve4_Link" />
    <child
      link="wheel4_Link" />
    <axis
      xyz="0 0 -1" />
  </joint>

  <gazebo>
    <plugin
      filename="ignition-gazebo-joint-state-publisher-system"
      name="ignition::gazebo::systems::JointStatePublisher">
      <topic>joint_states</topic>
    </plugin>

    <plugin
      filename="ignition-gazebo-joint-controller-system"
      name="ignition::gazebo::systems::JointController">
      <joint_name>wheel1_joint</joint_name>
      <initial_velocity>0.0</initial_velocity>
    </plugin>

    <plugin
      filename="ignition-gazebo-joint-controller-system"
      name="ignition::gazebo::systems::JointController">
      <joint_name>wheel2_joint</joint_name>
      <initial_velocity>0.0</initial_velocity>
    </plugin>

    <plugin
      filename="ignition-gazebo-joint-controller-system"
      name="ignition::gazebo::systems::JointController">
      <joint_name>wheel3_joint</joint_name>
      <initial_velocity>0.0</initial_velocity>
    </plugin>

    <plugin
      filename="ignition-gazebo-joint-controller-system"
      name="ignition::gazebo::systems::JointController">
      <joint_name>wheel4_joint</joint_name>
      <initial_velocity>0.0</initial_velocity>
    </plugin>
  </gazebo>

</robot>